<?xml version="1.0" encoding="UTF-8"?>
<!-- Generated by org.testng.reporters.JUnitReportReporter -->
<testsuite name="com.stc.test.RetryFailedTests" tests="6" time="0.021" ignored="0" failures="0" timestamp="10 Jan 2019 03:19:40 GMT" skipped="3" hostname="NYCGRMJSCHNIMAC" errors="1">
  <testcase name="test1" time="0.014" classname="com.stc.test.RetryFailedTests"/>
  <testcase name="test2" time="0.001" classname="com.stc.test.RetryFailedTests">
    <skipped/>
  </testcase> <!-- test2 -->
  <testcase name="test2" time="0.001" classname="com.stc.test.RetryFailedTests">
    <error type="java.lang.ArithmeticException" message="/ by zero">
      <![CDATA[java.lang.ArithmeticException: / by zero
	at com.stc.test.RetryFailedTests.test2(RetryFailedTests.java:15)
	at sun.reflect.NativeMethodAccessorImpl.invoke0(Native Method)
	at sun.reflect.NativeMethodAccessorImpl.invoke(Unknown Source)
	at sun.reflect.DelegatingMethodAccessorImpl.invoke(Unknown Source)
	at java.lang.reflect.Method.invoke(Unknown Source)
	at org.testng.internal.MethodInvocationHelper.invokeMethod(MethodInvocationHelper.java:104)
	at org.testng.internal.Invoker.invokeMethod(Invoker.java:645)
	at org.testng.internal.Invoker.retryFailed(Invoker.java:998)
	at org.testng.internal.Invoker.invokeTestMethods(Invoker.java:1200)
	at org.testng.internal.TestMethodWorker.invokeTestMethods(TestMethodWorker.java:129)
	at org.testng.internal.TestMethodWorker.run(TestMethodWorker.java:112)
	at org.testng.TestRunner.privateRun(TestRunner.java:756)
	at org.testng.TestRunner.run(TestRunner.java:610)
	at org.testng.SuiteRunner.runTest(SuiteRunner.java:387)
	at org.testng.SuiteRunner.runSequentially(SuiteRunner.java:382)
	at org.testng.SuiteRunner.privateRun(SuiteRunner.java:340)
	at org.testng.SuiteRunner.run(SuiteRunner.java:289)
	at org.testng.SuiteRunnerWorker.runSuite(SuiteRunnerWorker.java:52)
	at org.testng.SuiteRunnerWorker.run(SuiteRunnerWorker.java:86)
	at org.testng.TestNG.runSuitesSequentially(TestNG.java:1293)
	at org.testng.TestNG.runSuitesLocally(TestNG.java:1218)
	at org.testng.TestNG.runSuites(TestNG.java:1133)
	at org.testng.TestNG.run(TestNG.java:1104)
	at org.testng.remote.AbstractRemoteTestNG.run(AbstractRemoteTestNG.java:114)
	at org.testng.remote.RemoteTestNG.initAndRun(RemoteTestNG.java:251)
	at org.testng.remote.RemoteTestNG.main(RemoteTestNG.java:77)
]]>
    </error>
  </testcase> <!-- test2 -->
  <testcase name="test3" time="0.002" classname="com.stc.test.RetryFailedTests"/>
  <testcase name="test2" time="0.001" classname="com.stc.test.RetryFailedTests">
    <skipped/>
  </testcase> <!-- test2 -->
  <testcase name="test2" time="0.002" classname="com.stc.test.RetryFailedTests">
    <skipped/>
  </testcase> <!-- test2 -->
</testsuite> <!-- com.stc.test.RetryFailedTests -->
